Workbook

Sheet Totales
B2: Totales · reintegro Luciano v3
B3: 7 de septiembre de 2026. Sin diciembre futuro. Celdas amarillas editables.
B5: Supuestos
B6: Concepto | C6: Valor | D6: Nota
B7: Adelanto recibido (ARS) | C7: 600000 | D7: Pago en pesos hace tres meses.
B8: TC liquidación · compra oficial | C8: 1480 | D8: Cierre Nación 4 sep 2026.
B9: TC adelanto · compra BBVA 5 jun 2026 | C9: 1410 | D9: Punta compra BBVA.
B11: Resultado
B12: Concepto | C12: USD | D12: ARS
B13: Total gastos | C13: =SUM(Gastos!K6:K97) -> 1120.9994 | D13: =C13*C8 -> 1659079.1
B14: Adelanto recibido | C14: =C7/C9 -> 425.53191 | D14: =C7 -> 600000
B15: Saldo a devolver | C15: =C13-C14 -> 695.46748 | D15: =C15*C8 -> 1029291.9
B17: Por mes
B18: Mes | C18: Ítems | D18: USD | E18: ARS liquidación
B19: Enero 2026 | C19: =COUNTIF(Gastos!D6:D97,"2026-01") -> 8 | D19: =SUMIF(Gastos!D6:D97,"2026-01",Gastos!K6:K97) -> 86.93 | E19: =D19*$C$8 -> 128656.4
B20: Febrero 2026 | C20: =COUNTIF(Gastos!D6:D97,"2026-02") -> 6 | D20: =SUMIF(Gastos!D6:D97,"2026-02",Gastos!K6:K97) -> 85.16 | E20: =D20*$C$8 -> 126036.8
B21: Marzo 2026 | C21: =COUNTIF(Gastos!D6:D97,"2026-03") -> 9 | D21: =SUMIF(Gastos!D6:D97,"2026-03",Gastos!K6:K97) -> 127.67254 | E21: =D21*$C$8 -> 188955.36
B22: Abril 2026 | C22: =COUNTIF(Gastos!D6:D97,"2026-04") -> 15 | D22: =SUMIF(Gastos!D6:D97,"2026-04",Gastos!K6:K97) -> 218.72993 | E22: =D22*$C$8 -> 323720.3
B23: Mayo 2026 | C23: =COUNTIF(Gastos!D6:D97,"2026-05") -> 10 | D23: =SUMIF(Gastos!D6:D97,"2026-05",Gastos!K6:K97) -> 122.37962 | E23: =D23*$C$8 -> 181121.84
B24: Junio 2026 | C24: =COUNTIF(Gastos!D6:D97,"2026-06") -> 12 | D24: =SUMIF(Gastos!D6:D97,"2026-06",Gastos!K6:K97) -> 146.67034 | E24: =D24*$C$8 -> 217072.11
B25: Julio 2026 | C25: =COUNTIF(Gastos!D6:D97,"2026-07") -> 14 | D25: =SUMIF(Gastos!D6:D97,"2026-07",Gastos!K6:K97) -> 93.129812 | E25: =D25*$C$8 -> 137832.12
B26: Agosto 2026 | C26: =COUNTIF(Gastos!D6:D97,"2026-08") -> 16 | D26: =SUMIF(Gastos!D6:D97,"2026-08",Gastos!K6:K97) -> 213.81703 | E26: =D26*$C$8 -> 316449.2
B27: Septiembre 2026 | C27: =COUNTIF(Gastos!D6:D97,"2026-09") -> 2 | D27: =SUMIF(Gastos!D6:D97,"2026-09",Gastos!K6:K97) -> 26.510115 | E27: =D27*$C$8 -> 39234.97
B28: Total | C28: =SUM(C19:C27) -> 92 | D28: =SUM(D19:D27) -> 1120.9994 | E28: =SUM(E19:E27) -> 1659079.1
B30: Qué se sumó de este extracto y qué no
B31: Sumado: Grok XAI 12/08 98,17 USDC (el cargo de ~100). Uber 13/08 (4,65 y 4,40 USDC), 15/08 7,42 USDC y 31/08 ARS 5.971. DiDi 6/08 neto ARS 18.050. Se sacó el SuperGrok fechado en diciembre 2026. DigitalOcean 1/09 ya estaba. No hay YouTube. Google One, Spotify, Disney, Rappi, súper, Farmacity, Steam, YPF, grow, Cann-Be, transferencias a personas, conversiones cripto y pares pago+devolución de Railway/DO/Uber/DiDi no entran.

Sheet Gastos
B2: Gastos de Luciano · v3 · 7 septiembre 2026
B3: Sin fechas de diciembre 2026. Altas verdes desde extracto Mercado Pago. No incluye consumo personal.
B5: N | C5: Fecha | D5: Mes | E5: Invoice / origen | F5: Descripción | G5: Rubro | H5: Moneda | I5: Importe original | J5: TC | K5: USD | L5: ARS pagados | M5: ARS al TC liquidación | N5: Fuente
B6: 1 | C6: 46023 | D6: 2026-01 | E6: Invoice 0028 | F6: A.I. Tools - ChatGPT Plus subscription | G6: Herramientas AI | H6: USD | I6: 20 | J6: 1 | K6: 20 | M6: =IF(K6="","",K6*Totales!$C$8) -> 29600 | N6: Planilla Invoices de Luciano
B7: 2 | C7: 46023 | D7: 2026-01 | E7: Invoice 0027 | F7: A.I. Tools - Digital Ocean usage charge | G7: Herramientas AI | H7: USD | I7: 6 | J7: 1 | K7: 6 | M7: =IF(K7="","",K7*Totales!$C$8) -> 8880 | N7: Planilla Invoices de Luciano
B8: 3 | C8: 46023 | D8: 2026-01 | E8: Invoice 0028 | F8: Cloud storage for internal app | G8: Infra y cloud | H8: USD | I8: 6 | J8: 1 | K8: 6 | M8: =IF(K8="","",K8*Totales!$C$8) -> 8880 | N8: Planilla Invoices de Luciano
B9: 4 | C9: 46029 | D9: 2026-01 | E9: Invoice 0037 | F9: DigitalOcean | G9: Infra y cloud | H9: USD | I9: 4.93 | J9: 1 | K9: 4.93 | M9: =IF(K9="","",K9*Totales!$C$8) -> 7296.4 | N9: Planilla Invoices de Luciano
B10: 5 | C10: 46034 | D10: 2026-01 | E10: Invoice 0027 | F10: A.I. Tools - Cursor Pro subscription | G10: Herramientas AI | H10: USD | I10: 20 | J10: 1 | K10: 20 | M10: =IF(K10="","",K10*Totales!$C$8) -> 29600 | N10: Planilla Invoices de Luciano
B11: 6 | C11: 46037 | D11: 2026-01 | E11: Invoice 0027 | F11: A.I. Tools - OpenAI API usage credit #1 | G11: Herramientas AI | H11: USD | I11: 5 | J11: 1 | K11: 5 | M11: =IF(K11="","",K11*Totales!$C$8) -> 7400 | N11: Planilla Invoices de Luciano
B12: 7 | C12: 46037 | D12: 2026-01 | E12: Invoice 0027 | F12: A.I. Tools - OpenAI API usage credit #2 | G12: Herramientas AI | H12: USD | I12: 5 | J12: 1 | K12: 5 | M12: =IF(K12="","",K12*Totales!$C$8) -> 7400 | N12: Planilla Invoices de Luciano
B13: 8 | C13: 46053 | D13: 2026-01 | E13: Invoice 0027 | F13: A.I. Tools - Claude Pro subscription | G13: Herramientas AI | H13: USD | I13: 20 | J13: 1 | K13: 20 | M13: =IF(K13="","",K13*Totales!$C$8) -> 29600 | N13: Planilla Invoices de Luciano
B14: 9 | C14: 46054 | D14: 2026-02 | E14: Invoice 0028 | F14: A.I. Tools - ChatGPT Plus subscription | G14: Herramientas AI | H14: USD | I14: 20 | J14: 1 | K14: 20 | M14: =IF(K14="","",K14*Totales!$C$8) -> 29600 | N14: Planilla Invoices de Luciano
B15: 10 | C15: 46054 | D15: 2026-02 | E15: Invoice 0028 | F15: Railway Hobby plan | G15: Infra y cloud | H15: USD | I15: 5 | J15: 1 | K15: 5 | M15: =IF(K15="","",K15*Totales!$C$8) -> 7400 | N15: Planilla Invoices de Luciano
B16: 11 | C16: 46054 | D16: 2026-02 | E16: Invoice 0028 | F16: Railway Pro plan | G16: Infra y cloud | H16: USD | I16: 9.81 | J16: 1 | K16: 9.81 | M16: =IF(K16="","",K16*Totales!$C$8) -> 14518.8 | N16: Planilla Invoices de Luciano
B17: 12 | C17: 46054 | D17: 2026-02 | E17: Invoice 0028 | F17: Vercel Pro plan | G17: Infra y cloud | H17: USD | I17: 20.35 | J17: 1 | K17: 20.35 | M17: =IF(K17="","",K17*Totales!$C$8) -> 30118 | N17: Planilla Invoices de Luciano
... B27: 22 | C27: 46100 | D27: 2026-03 | E27: Invoice 0028 | F27: A.I. Tools - OpenAI API credit usage | G27: Herramientas AI | H27: USD | I27: 10.08 | J27: 1 | K27: 10.08 | M27: =IF(K27="","",K27*Totales!$C$8) -> 14918.4 | N27: Planilla Invoices de Luciano
B28: 23 | C28: 46107 | D28: 2026-03 | E28: Invoice 0028 | F28: Consumptions at the hotel - Buidler Fest | G28: Eventos y extras | H28: ARS | I28: 38500 | J28: 1515 | K28: 25.412541 | L28: 38500 | M28: =IF(K28="","",K28*Totales!$C$8) -> 37610.561 | N28: Planilla Invoices de Luciano
B29: 24 | C29: 46113 | D29: 2026-04 | E29: Invoice 0028 | F29: A.I. Tools - Claude Pro plan | G29: Herramientas AI | H29: USD | I29: 20 | J29: 1 | K29: 20 | M29: =IF(K29="","",K29*Totales!$C$8) -> 29600 | N29: Planilla Invoices de Luciano
B30: 25 | C30: 46113 | D30: 2026-04 | E30: Invoice 0030 | F30: A.I. Tools - Claude Pro subscription | G30: Herramientas AI | H30: USD | I30: 20 | J30: 1 | K30: 20 | M30: =IF(K30="","",K30*Totales!$C$8) -> 29600 | N30: Planilla Invoices de Luciano
B31: 26 | C31: 46113 | D31: 2026-04 | E31: Invoice 0030 | F31: Digital Ocean subscription | G31: Infra y cloud | H31: USD | I31: 6 | J31: 1 | K31: 6 | M31: =IF(K31="","",K31*Totales!$C$8) -> 8880 | N31: Planilla Invoices de Luciano
B32: 27 | C32: 46113 | D32: 2026-04 | E32: Invoice 0028 | F32: Vercel Pro plan | G32: Infra y cloud | H32: USD | I32: 20 | J32: 1 | K32: 20 | M32: =IF(K32="","",K32*Totales!$C$8) -> 29600 | N32: Planilla Invoices de Luciano
B33: 28 | C33: 46114 | D33: 2026-04 | E33: Invoice 0028 | F33: Vercel usage for internal app | G33: Infra y cloud | H33: USD | I33: 63.39 | J33: 1 | K33: 63.39 | M33: =IF(K33="","",K33*Totales!$C$8) -> 93817.2 | N33: Planilla Invoices de Luciano
B34: 29 | C34: 46119 | D34: 2026-04 | E34: Invoice 0037 | F34: Railway Hobby plan | G34: Infra y cloud | H34: USD | I34: 5 | J34: 1 | K34: 5 | M34: =IF(K34="","",K34*Totales!$C$8) -> 7400 | N34: Planilla Invoices de Luciano
B35: 30 | C35: 46125 | D35: 2026-04 | E35: Invoice 0030 | F35: Uber | G35: Movilidad | H35: ARS | I35: 21880 | J35: 1515 | K35: 14.442244 | L35: 21880 | M35: =IF(K35="","",K35*Totales!$C$8) -> 21374.521 | N35: Planilla Invoices de Luciano
B36: 31 | C36: 46127 | D36: 2026-04 | E36: Invoice 0030 | F36: Uber during Escobar workshop | G36: Movilidad | H36: ARS | I36: 2350 | J36: 1515 | K36: 1.5511551 | L36: 2350 | M36: =IF(K36="","",K36*Totales!$C$8) -> 2295.7096 | N36: Planilla Invoices de Luciano
B37: 32 | C37: 46127 | D37: 2026-04 | E37: Invoice 0030 | F37: Uber from the office | G37: Movilidad | H37: ARS | I37: 17790 | J37: 1515 | K37: 11.742574 | L37: 17790 | M37: =IF(K37="","",K37*Totales!$C$8) -> 17379.01 | N37: Planilla Invoices de Luciano
B38: 33 | C38: 46127 | D38: 2026-04 | E38: Invoice 0030 | F38: Uber from the office | G38: Movilidad | H38: ARS | I38: 4985 | J38: 1515 | K38: 3.290429 | L38: 4985 | M38: =IF(K38="","",K38*Totales!$C$8) -> 4869.835 | N38: Planilla Invoices de Luciano
B39: 34 | C39: 46127 | D39: 2026-04 | E39: Invoice 0030 | F39: Uber to the office | G39: Movilidad | H39: ARS | I39: 4374 | J39: 1515 | K39: 2.8871287 | L39: 4374 | M39: =IF(K39="","",K39*Totales!$C$8) -> 4272.9505 | N39: Planilla Invoices de Luciano
B40: 35 | C40: 46133 | D40: 2026-04 | E40: Invoice 0030 | F40: Uber to bring merchandise to the office (return) - Universities Day | G40: Movilidad | H40: ARS | I40: 11130 | J40: 1515 | K40: 7.3465347 | L40: 11130 | M40: =IF(K40="","",K40*Totales!$C$8) -> 10872.871 | N40: Planilla Invoices de Luciano
B41: 36 | C41: 46133 | D41: 2026-04 | E41: Invoice 0030 | F41: Uber to bring merchandise to the office - Universities Day | G41: Movilidad | H41: ARS | I41: 14582 | J41: 1515 | K41: 9.6250825 | L41: 14582 | M41: =IF(K41="","",K41*Totales!$C$8) -> 14245.122 | N41: Planilla Invoices de Luciano
B42: 37 | C42: 46134 | D42: 2026-04 | E42: Invoice 0030 | F42: Uber to Escobar workshop | G42: Movilidad | H42: ARS | I42: 31918 | J42: 1515 | K42: 21.067987 | L42: 31918 | M42: =IF(K42="","",K42*Totales!$C$8) -> 31180.62 | N42: Planilla Invoices de Luciano
B43: 38 | C43: 46135 | D43: 2026-04 | E43: Invoice 0030 | F43: Late Uber from the office | G43: Movilidad | H43: ARS | I43: 18766 | J43: 1515 | K43: 12.386799 | L43: 18766 | M43: =IF(K43="","",K43*Totales!$C$8) -> 18332.462 | N43: Planilla Invoices de Luciano
B44: 39 | C44: 46143 | D44: 2026-05 | E44: Invoice 0030 | F44: Digital Ocean subscription | G44: Infra y cloud | H44: USD | I44: 6 | J44: 1 | K44: 6 | M44: =IF(K44="","",K44*Totales!$C$8) -> 8880 | N44: Planilla Invoices de Luciano
B45: 40 | C45: 46143 | D45: 2026-05 | E45: Invoice 0030 | F45: Railway subscription | G45: Infra y cloud | H45: USD | I45: 5 | J45: 1 | K45: 5 | M45: =IF(K45="","",K45*Totales!$C$8) -> 7400 | N45: Planilla Invoices de Luciano
B46: 41 | C46: 46146 | D46: 2026-05 | E46: Invoice 0030 | F46: Uber from the office | G46: Movilidad | H46: ARS | I46: 4081 | J46: 1515 | K46: 2.6937294 | L46: 4081 | M46: =IF(K46="","",K46*Totales!$C$8) -> 3986.7195 | N46: Planilla Invoices de Luciano
B47: 42 | C47: 46151 | D47: 2026-05 | E47: Invoice 0030 | F47: Uber to the office for Product Day event (rainy Saturday) | G47: Movilidad | H47: ARS | I47: 19426 | J47: 1515 | K47: 12.822442 | L47: 19426 | M47: =IF(K47="","",K47*Totales!$C$8) -> 18977.215 | N47: Planilla Invoices de Luciano
B48: 43 | C48: 46155 | D48: 2026-05 | E48: Invoice 0036 | F48: Late return from office Uber trip | G48: Movilidad | H48: ARS | I48: 7119 | J48: 1450 | K48: 4.9096552 | L48: 7119 | M48: =IF(K48="","",K48*Totales!$C$8) -> 7266.2897 | N48: Planilla Invoices de Luciano
B49: 44 | C49: 46155 | D49: 2026-05 | E49: Invoice 0030 | F49: Vercel Subscription | G49: Infra y cloud | H49: USD | I49: 20 | J49: 1 | K49: 20 | M49: =IF(K49="","",K49*Totales!$C$8) -> 29600 | N49: Planilla Invoices de Luciano
B50: 45 | C50: 46156 | D50: 2026-05 | E50: Invoice 0036 | F50: Late return from office Uber trip | G50: Movilidad | H50: ARS | I50: 15883 | J50: 1450 | K50: 10.953793 | L50: 15883 | M50: =IF(K50="","",K50*Totales!$C$8) -> 16211.614 | N50: Planilla Invoices de Luciano
B51: 46 | C51: 46163 | D51: 2026-05 | E51: Invoice 0030 | F51: A.I. tools - paper.design subscription | G51: Herramientas AI | H51: USD | I51: 20 | J51: 1 | K51: 20 | M51: =IF(K51="","",K51*Totales!$C$8) -> 29600 | N51: Planilla Invoices de Luciano
...

Sheet Criterio
B2: Criterio v3
B5: El Grok de 98,17 USDC del 12/08 es el cargo grande que faltaba en la planilla de invoices. El de 24 USD del 4/08 (tarjeta BBVA) se mantiene aparte. El de 9,90 del 12/07 también. No se inventó un cargo de 100 redondos.
